{
 "cells": [
  {
   "cell_type": "markdown",
   "id": "7dd19066-77ac-45d1-8d5e-6bbb467d2b90",
   "metadata": {},
   "source": [
    "# Sección 1: Cargar y Preprocesar Datos"
   ]
  },
  {
   "cell_type": "code",
   "execution_count": 73,
   "id": "6d85d307-b12f-47ec-9ac5-07c200544995",
   "metadata": {},
   "outputs": [
    {
     "name": "stdout",
     "output_type": "stream",
     "text": [
      "Cargando datos...\n",
      "Datos cargados: 2878 registros, 3 columnas\n",
      "Limpiando datos...\n",
      "Columnas disponibles después de limpiar los datos: Index(['username', 'timestamp', 'comment', 'comment_limpio', 'tokens'], dtype='object')\n",
      "Mostrando resultados de limpieza de datos...\n",
      "           username                 timestamp  \\\n",
      "0      @MarcoGilerM  2023-09-11T13:37:46.000Z   \n",
      "1  @JoseAnt40060050  2023-09-01T22:39:33.000Z   \n",
      "2  @MariaMa99904828  2023-05-31T00:22:19.000Z   \n",
      "3      @patsurfer71  2023-03-30T12:27:34.000Z   \n",
      "4  @Joselui48173725  2023-02-01T13:43:37.000Z   \n",
      "\n",
      "                                             comment  \\\n",
      "0  eso no es todo al realizarse la transferencia ...   \n",
      "1  nunca entregaste un hospital para la zona sur ...   \n",
      "2  a mas de adefesio sinverguenza charlatan cuand...   \n",
      "3  jipijapa necesita un hospital general que pued...   \n",
      "4  hay jente que tienen caca en el serebropor k v...   \n",
      "\n",
      "                                      comment_limpio  \\\n",
      "0  eso no es todo al realizarse la transferencia ...   \n",
      "1  nunca entregaste un hospital para la zona sur ...   \n",
      "2  a mas de adefesio sinverguenza charlatan cuand...   \n",
      "3  jipijapa necesita un hospital general que pued...   \n",
      "4  hay jente que tienen caca en el serebropor k v...   \n",
      "\n",
      "                                              tokens  \n",
      "0  [eso, no, es, todo, al, realizarse, la, transf...  \n",
      "1  [nunca, entregaste, un, hospital, para, la, zo...  \n",
      "2  [a, mas, de, adefesio, sinverguenza, charlatan...  \n",
      "3  [jipijapa, necesita, un, hospital, general, qu...  \n",
      "4  [hay, jente, que, tienen, caca, en, el, serebr...  \n"
     ]
    }
   ],
   "source": [
    "# Sección 1: Cargar y Preprocesar Datos\n",
    "import pandas as pd\n",
    "import numpy as np\n",
    "import re\n",
    "import string\n",
    "from sklearn.model_selection import train_test_split\n",
    "from tensorflow.keras.preprocessing.text import Tokenizer\n",
    "from tensorflow.keras.preprocessing.sequence import pad_sequences\n",
    "from tensorflow.keras.utils import to_categorical\n",
    "import matplotlib.pyplot as plt\n",
    "import seaborn as sns\n",
    "\n",
    "# Función para limpiar texto\n",
    "def limpiar_texto(text):\n",
    "    text = text.lower()\n",
    "    text = re.sub(r\"[{}]\".format(string.punctuation), \"\", text)\n",
    "    text = re.sub(r\"\\s+\", \" \", text).strip()\n",
    "    return text\n",
    "\n",
    "# Función para tokenizar texto\n",
    "def tokenizar_texto(text):\n",
    "    return text.split()\n",
    "\n",
    "# Cargar datos\n",
    "print(\"Cargando datos...\")\n",
    "df = pd.read_csv('datasets/datos_combinados_1.csv')\n",
    "print(f\"Datos cargados: {df.shape[0]} registros, {df.shape[1]} columnas\")\n",
    "\n",
    "# Limpieza de datos\n",
    "print(\"Limpiando datos...\")\n",
    "df['comment_limpio'] = df['comment'].apply(limpiar_texto)\n",
    "df['tokens'] = df['comment_limpio'].apply(tokenizar_texto)\n",
    "print(f\"Columnas disponibles después de limpiar los datos: {df.columns}\")\n",
    "\n",
    "# Visualización de los datos limpios\n",
    "print(\"Mostrando resultados de limpieza de datos...\")\n",
    "print(df.head())"
   ]
  },
  {
   "cell_type": "markdown",
   "id": "ef540407-9aff-43b7-b0db-4cc1c0446ebd",
   "metadata": {},
   "source": [
    "# Sección 2: Análisis de Sentimientos"
   ]
  },
  {
   "cell_type": "code",
   "execution_count": 74,
   "id": "24068515-2453-4d7e-9436-91bce91021e6",
   "metadata": {},
   "outputs": [
    {
     "name": "stdout",
     "output_type": "stream",
     "text": [
      "Análisis de sentimientos...\n",
      "Columnas disponibles después del análisis de sentimientos: Index(['username', 'timestamp', 'comment', 'comment_limpio', 'tokens',\n",
      "       'sentimiento', 'aspecto'],\n",
      "      dtype='object')\n"
     ]
    }
   ],
   "source": [
    "# Sección 2: Análisis de Sentimientos\n",
    "from textblob import TextBlob\n",
    "\n",
    "def detectar_sentimiento(text):\n",
    "    analysis = TextBlob(text)\n",
    "    if analysis.sentiment.polarity > 0:\n",
    "        return 1  # Positivo\n",
    "    elif analysis.sentiment.polarity < 0:\n",
    "        return -1  # Negativo\n",
    "    else:\n",
    "        return 0  # Neutral\n",
    "\n",
    "def detectar_aspecto(text):\n",
    "    return 'neutral'  # Implementar lógica de detección de aspectos\n",
    "\n",
    "print(\"Análisis de sentimientos...\")\n",
    "df['sentimiento'] = df['comment_limpio'].apply(detectar_sentimiento)\n",
    "df['aspecto'] = df['comment_limpio'].apply(detectar_aspecto)\n",
    "print(f\"Columnas disponibles después del análisis de sentimientos: {df.columns}\")"
   ]
  },
  {
   "cell_type": "markdown",
   "id": "7132b4c6-fd75-416a-ab01-cbd70ac7f740",
   "metadata": {},
   "source": [
    "# Sección 3: Preparación de Datos para el Modelo"
   ]
  },
  {
   "cell_type": "code",
   "execution_count": 75,
   "id": "e37c794b-ad7c-41be-be35-cbcee8211a13",
   "metadata": {},
   "outputs": [
    {
     "name": "stdout",
     "output_type": "stream",
     "text": [
      "Datos antes del mapeo de sentimiento:\n",
      "                                             comment  sentimiento\n",
      "0  eso no es todo al realizarse la transferencia ...            0\n",
      "1  nunca entregaste un hospital para la zona sur ...            0\n",
      "2  a mas de adefesio sinverguenza charlatan cuand...            0\n",
      "3  jipijapa necesita un hospital general que pued...            1\n",
      "4  hay jente que tienen caca en el serebropor k v...            0\n",
      "Valores únicos en la columna 'sentimiento' antes del mapeo: [ 0  1 -1]\n",
      "Valores únicos en la columna 'sentimiento' después del mapeo: [0 1 2]\n",
      "Valores NaN antes de eliminar: 0\n",
      "Valores NaN después de eliminar: 0\n",
      "Valores únicos en 'sentimiento' después de eliminar NaN: [0 1 2]\n",
      "Valores únicos finales en 'sentimiento': [0 1 2]\n",
      "Tamaño del dataframe después de la limpieza: (2878, 7)\n",
      "Datos después de la limpieza:\n",
      "                                             comment  sentimiento\n",
      "0  eso no es todo al realizarse la transferencia ...            0\n",
      "1  nunca entregaste un hospital para la zona sur ...            0\n",
      "2  a mas de adefesio sinverguenza charlatan cuand...            0\n",
      "3  jipijapa necesita un hospital general que pued...            1\n",
      "4  hay jente que tienen caca en el serebropor k v...            0\n",
      "Datos de entrenamiento: (2014, 100)\n",
      "Datos de validación: (432, 100)\n",
      "Datos de prueba: (432, 100)\n"
     ]
    }
   ],
   "source": [
    "# Preparación de Datos para el Modelo\n",
    "max_words = 10000\n",
    "max_len = 100\n",
    "tokenizer = Tokenizer(num_words=max_words)\n",
    "tokenizer.fit_on_texts(df['comment_limpio'])\n",
    "sequences = tokenizer.texts_to_sequences(df['comment_limpio'])\n",
    "word_index = tokenizer.word_index\n",
    "data = pad_sequences(sequences, maxlen=max_len)\n",
    "\n",
    "# Paso 1: Verificar los primeros registros antes del mapeo\n",
    "print(\"Datos antes del mapeo de sentimiento:\")\n",
    "print(df[['comment', 'sentimiento']].head())\n",
    "\n",
    "# Paso 2: Revisar los valores únicos en la columna original 'sentimiento' antes del mapeo\n",
    "print(f\"Valores únicos en la columna 'sentimiento' antes del mapeo: {df['sentimiento'].unique()}\")\n",
    "\n",
    "# Paso 3: Filtrar sólo los valores que están en el mapping\n",
    "valid_sentimientos = ['positivo', 'negativo', 'neutral', 0, 1, -1]  # Añadir valores numéricos que ya están presentes\n",
    "df = df[df['sentimiento'].isin(valid_sentimientos)]\n",
    "\n",
    "# Paso 4: Mapeo de sentimientos a enteros\n",
    "sentimiento_mapping = {'positivo': 0, 'negativo': 1, 'neutral': 2, 0: 0, 1: 1, -1: 2}  # Ajustar el mapping para incluir -1\n",
    "df['sentimiento'] = df['sentimiento'].map(sentimiento_mapping)\n",
    "\n",
    "# Paso 5: Verificar valores únicos después del mapeo\n",
    "print(f\"Valores únicos en la columna 'sentimiento' después del mapeo: {df['sentimiento'].unique()}\")\n",
    "\n",
    "# Paso 6: Verificar y eliminar valores nulos en 'sentimiento'\n",
    "print(f\"Valores NaN antes de eliminar: {df['sentimiento'].isna().sum()}\")\n",
    "df.dropna(subset=['sentimiento'], inplace=True)\n",
    "print(f\"Valores NaN después de eliminar: {df['sentimiento'].isna().sum()}\")\n",
    "\n",
    "# Paso 7: Verificar valores únicos después de eliminar NaN\n",
    "unique_values = df['sentimiento'].unique()\n",
    "print(f\"Valores únicos en 'sentimiento' después de eliminar NaN: {unique_values}\")\n",
    "\n",
    "# Paso 8: Asegurarse de que los valores en 'sentimiento' sean enteros y positivos\n",
    "if len(df) == 0:\n",
    "    print(\"Error: No hay datos en 'sentimiento' después de la limpieza.\")\n",
    "else:\n",
    "    df['sentimiento'] = df['sentimiento'].astype(int)\n",
    "    print(f\"Valores únicos finales en 'sentimiento': {df['sentimiento'].unique()}\")  # Debería imprimir [0 1 2]\n",
    "\n",
    "# Paso 9: Verificar tamaño del dataframe después de la limpieza\n",
    "print(f\"Tamaño del dataframe después de la limpieza: {df.shape}\")\n",
    "\n",
    "# Paso 10: Imprimir los primeros registros después de la limpieza\n",
    "print(\"Datos después de la limpieza:\")\n",
    "print(df[['comment', 'sentimiento']].head())\n",
    "\n",
    "# Paso 11: Convertir las etiquetas a formato categórico\n",
    "if df['sentimiento'].size > 0:\n",
    "    labels = to_categorical(df['sentimiento'])\n",
    "else:\n",
    "    raise ValueError(\"No hay datos válidos en 'sentimiento' después de la limpieza.\")\n",
    "\n",
    "# Paso 12: División de datos en entrenamiento, validación y prueba\n",
    "X_train, X_temp, y_train, y_temp = train_test_split(data, labels, test_size=0.3, random_state=42)\n",
    "X_val, X_test, y_val, y_test = train_test_split(X_temp, y_temp, test_size=0.5, random_state=42)\n",
    "\n",
    "print(f\"Datos de entrenamiento: {X_train.shape}\")\n",
    "print(f\"Datos de validación: {X_val.shape}\")\n",
    "print(f\"Datos de prueba: {X_test.shape}\")"
   ]
  },
  {
   "cell_type": "markdown",
   "id": "dde23bf2-9f2c-44d4-aac8-66ed85f6b989",
   "metadata": {},
   "source": [
    "# Sección 4: Definición y Entrenamiento del Modelo RNN"
   ]
  },
  {
   "cell_type": "code",
   "execution_count": 76,
   "id": "71306f9f-e664-42fe-a6f4-a30646906194",
   "metadata": {},
   "outputs": [
    {
     "name": "stdout",
     "output_type": "stream",
     "text": [
      "Entrenando el modelo...\n",
      "Epoch 1/10\n",
      "\u001b[1m63/63\u001b[0m \u001b[32m━━━━━━━━━━━━━━━━━━━━\u001b[0m\u001b[37m\u001b[0m \u001b[1m28s\u001b[0m 232ms/step - accuracy: 0.8348 - loss: 0.5204 - val_accuracy: 0.9190 - val_loss: 0.3092\n",
      "Epoch 2/10\n",
      "\u001b[1m63/63\u001b[0m \u001b[32m━━━━━━━━━━━━━━━━━━━━\u001b[0m\u001b[37m\u001b[0m \u001b[1m13s\u001b[0m 209ms/step - accuracy: 0.9192 - loss: 0.2936 - val_accuracy: 0.8264 - val_loss: 0.3927\n",
      "Epoch 3/10\n",
      "\u001b[1m63/63\u001b[0m \u001b[32m━━━━━━━━━━━━━━━━━━━━\u001b[0m\u001b[37m\u001b[0m \u001b[1m13s\u001b[0m 210ms/step - accuracy: 0.9647 - loss: 0.1290 - val_accuracy: 0.9236 - val_loss: 0.3225\n",
      "Epoch 4/10\n",
      "\u001b[1m63/63\u001b[0m \u001b[32m━━━━━━━━━━━━━━━━━━━━\u001b[0m\u001b[37m\u001b[0m \u001b[1m13s\u001b[0m 206ms/step - accuracy: 0.9838 - loss: 0.0612 - val_accuracy: 0.8727 - val_loss: 0.4222\n",
      "Epoch 5/10\n",
      "\u001b[1m63/63\u001b[0m \u001b[32m━━━━━━━━━━━━━━━━━━━━\u001b[0m\u001b[37m\u001b[0m \u001b[1m13s\u001b[0m 208ms/step - accuracy: 0.9793 - loss: 0.0489 - val_accuracy: 0.8912 - val_loss: 0.4393\n",
      "Epoch 6/10\n",
      "\u001b[1m63/63\u001b[0m \u001b[32m━━━━━━━━━━━━━━━━━━━━\u001b[0m\u001b[37m\u001b[0m \u001b[1m13s\u001b[0m 208ms/step - accuracy: 0.9889 - loss: 0.0324 - val_accuracy: 0.8588 - val_loss: 0.5629\n",
      "Epoch 7/10\n",
      "\u001b[1m63/63\u001b[0m \u001b[32m━━━━━━━━━━━━━━━━━━━━\u001b[0m\u001b[37m\u001b[0m \u001b[1m14s\u001b[0m 216ms/step - accuracy: 0.9911 - loss: 0.0350 - val_accuracy: 0.9236 - val_loss: 0.4369\n",
      "Epoch 8/10\n",
      "\u001b[1m63/63\u001b[0m \u001b[32m━━━━━━━━━━━━━━━━━━━━\u001b[0m\u001b[37m\u001b[0m \u001b[1m20s\u001b[0m 209ms/step - accuracy: 0.9999 - loss: 0.0085 - val_accuracy: 0.8750 - val_loss: 0.6116\n",
      "Epoch 9/10\n",
      "\u001b[1m63/63\u001b[0m \u001b[32m━━━━━━━━━━━━━━━━━━━━\u001b[0m\u001b[37m\u001b[0m \u001b[1m13s\u001b[0m 211ms/step - accuracy: 0.9993 - loss: 0.0055 - val_accuracy: 0.8773 - val_loss: 0.5903\n",
      "Epoch 10/10\n",
      "\u001b[1m63/63\u001b[0m \u001b[32m━━━━━━━━━━━━━━━━━━━━\u001b[0m\u001b[37m\u001b[0m \u001b[1m14s\u001b[0m 220ms/step - accuracy: 1.0000 - loss: 0.0034 - val_accuracy: 0.8981 - val_loss: 0.5688\n"
     ]
    }
   ],
   "source": [
    "from tensorflow.keras.models import Sequential\n",
    "from tensorflow.keras.layers import Embedding, LSTM, Dense, Dropout, Bidirectional\n",
    "from tensorflow.keras.optimizers import Adam\n",
    "\n",
    "embedding_dim = 100\n",
    "\n",
    "model = Sequential()\n",
    "model.add(Embedding(input_dim=max_words, output_dim=embedding_dim))\n",
    "model.add(Bidirectional(LSTM(64, return_sequences=True)))\n",
    "model.add(Dropout(0.5))\n",
    "model.add(Bidirectional(LSTM(32)))\n",
    "model.add(Dense(3, activation='softmax'))\n",
    "\n",
    "model.compile(optimizer=Adam(learning_rate=0.001), loss='categorical_crossentropy', metrics=['accuracy'])\n",
    "\n",
    "print(\"Entrenando el modelo...\")\n",
    "history = model.fit(X_train, y_train, epochs=10, batch_size=32, validation_data=(X_val, y_val))"
   ]
  },
  {
   "cell_type": "markdown",
   "id": "2bc18cac-827f-4650-b213-9273fcdad8d0",
   "metadata": {},
   "source": [
    "# Sección 6: Optimización del Modelo con Algoritmo Genético (GA)"
   ]
  },
  {
   "cell_type": "code",
   "execution_count": 77,
   "id": "974e06d6-8055-4481-b550-31151bb8eb57",
   "metadata": {},
   "outputs": [
    {
     "name": "stderr",
     "output_type": "stream",
     "text": [
      "C:\\Users\\Erick Carreño\\AppData\\Local\\Programs\\Python\\Python312\\Lib\\site-packages\\keras\\src\\layers\\core\\embedding.py:90: UserWarning: Argument `input_length` is deprecated. Just remove it.\n",
      "  warnings.warn(\n"
     ]
    },
    {
     "data": {
      "text/html": [
       "<pre style=\"white-space:pre;overflow-x:auto;line-height:normal;font-family:Menlo,'DejaVu Sans Mono',consolas,'Courier New',monospace\"><span style=\"font-weight: bold\">Model: \"sequential_10\"</span>\n",
       "</pre>\n"
      ],
      "text/plain": [
       "\u001b[1mModel: \"sequential_10\"\u001b[0m\n"
      ]
     },
     "metadata": {},
     "output_type": "display_data"
    },
    {
     "data": {
      "text/html": [
       "<pre style=\"white-space:pre;overflow-x:auto;line-height:normal;font-family:Menlo,'DejaVu Sans Mono',consolas,'Courier New',monospace\">┏━━━━━━━━━━━━━━━━━━━━━━━━━━━━━━━━━━━━━━┳━━━━━━━━━━━━━━━━━━━━━━━━━━━━━┳━━━━━━━━━━━━━━━━━┓\n",
       "┃<span style=\"font-weight: bold\"> Layer (type)                         </span>┃<span style=\"font-weight: bold\"> Output Shape                </span>┃<span style=\"font-weight: bold\">         Param # </span>┃\n",
       "┡━━━━━━━━━━━━━━━━━━━━━━━━━━━━━━━━━━━━━━╇━━━━━━━━━━━━━━━━━━━━━━━━━━━━━╇━━━━━━━━━━━━━━━━━┩\n",
       "│ embedding_10 (<span style=\"color: #0087ff; text-decoration-color: #0087ff\">Embedding</span>)             │ ?                           │     <span style=\"color: #00af00; text-decoration-color: #00af00\">0</span> (unbuilt) │\n",
       "├──────────────────────────────────────┼─────────────────────────────┼─────────────────┤\n",
       "│ bidirectional_18 (<span style=\"color: #0087ff; text-decoration-color: #0087ff\">Bidirectional</span>)     │ ?                           │     <span style=\"color: #00af00; text-decoration-color: #00af00\">0</span> (unbuilt) │\n",
       "├──────────────────────────────────────┼─────────────────────────────┼─────────────────┤\n",
       "│ dropout_10 (<span style=\"color: #0087ff; text-decoration-color: #0087ff\">Dropout</span>)                 │ ?                           │     <span style=\"color: #00af00; text-decoration-color: #00af00\">0</span> (unbuilt) │\n",
       "├──────────────────────────────────────┼─────────────────────────────┼─────────────────┤\n",
       "│ bidirectional_19 (<span style=\"color: #0087ff; text-decoration-color: #0087ff\">Bidirectional</span>)     │ ?                           │     <span style=\"color: #00af00; text-decoration-color: #00af00\">0</span> (unbuilt) │\n",
       "├──────────────────────────────────────┼─────────────────────────────┼─────────────────┤\n",
       "│ dense_10 (<span style=\"color: #0087ff; text-decoration-color: #0087ff\">Dense</span>)                     │ ?                           │     <span style=\"color: #00af00; text-decoration-color: #00af00\">0</span> (unbuilt) │\n",
       "└──────────────────────────────────────┴─────────────────────────────┴─────────────────┘\n",
       "</pre>\n"
      ],
      "text/plain": [
       "┏━━━━━━━━━━━━━━━━━━━━━━━━━━━━━━━━━━━━━━┳━━━━━━━━━━━━━━━━━━━━━━━━━━━━━┳━━━━━━━━━━━━━━━━━┓\n",
       "┃\u001b[1m \u001b[0m\u001b[1mLayer (type)                        \u001b[0m\u001b[1m \u001b[0m┃\u001b[1m \u001b[0m\u001b[1mOutput Shape               \u001b[0m\u001b[1m \u001b[0m┃\u001b[1m \u001b[0m\u001b[1m        Param #\u001b[0m\u001b[1m \u001b[0m┃\n",
       "┡━━━━━━━━━━━━━━━━━━━━━━━━━━━━━━━━━━━━━━╇━━━━━━━━━━━━━━━━━━━━━━━━━━━━━╇━━━━━━━━━━━━━━━━━┩\n",
       "│ embedding_10 (\u001b[38;5;33mEmbedding\u001b[0m)             │ ?                           │     \u001b[38;5;34m0\u001b[0m (unbuilt) │\n",
       "├──────────────────────────────────────┼─────────────────────────────┼─────────────────┤\n",
       "│ bidirectional_18 (\u001b[38;5;33mBidirectional\u001b[0m)     │ ?                           │     \u001b[38;5;34m0\u001b[0m (unbuilt) │\n",
       "├──────────────────────────────────────┼─────────────────────────────┼─────────────────┤\n",
       "│ dropout_10 (\u001b[38;5;33mDropout\u001b[0m)                 │ ?                           │     \u001b[38;5;34m0\u001b[0m (unbuilt) │\n",
       "├──────────────────────────────────────┼─────────────────────────────┼─────────────────┤\n",
       "│ bidirectional_19 (\u001b[38;5;33mBidirectional\u001b[0m)     │ ?                           │     \u001b[38;5;34m0\u001b[0m (unbuilt) │\n",
       "├──────────────────────────────────────┼─────────────────────────────┼─────────────────┤\n",
       "│ dense_10 (\u001b[38;5;33mDense\u001b[0m)                     │ ?                           │     \u001b[38;5;34m0\u001b[0m (unbuilt) │\n",
       "└──────────────────────────────────────┴─────────────────────────────┴─────────────────┘\n"
      ]
     },
     "metadata": {},
     "output_type": "display_data"
    },
    {
     "data": {
      "text/html": [
       "<pre style=\"white-space:pre;overflow-x:auto;line-height:normal;font-family:Menlo,'DejaVu Sans Mono',consolas,'Courier New',monospace\"><span style=\"font-weight: bold\"> Total params: </span><span style=\"color: #00af00; text-decoration-color: #00af00\">0</span> (0.00 B)\n",
       "</pre>\n"
      ],
      "text/plain": [
       "\u001b[1m Total params: \u001b[0m\u001b[38;5;34m0\u001b[0m (0.00 B)\n"
      ]
     },
     "metadata": {},
     "output_type": "display_data"
    },
    {
     "data": {
      "text/html": [
       "<pre style=\"white-space:pre;overflow-x:auto;line-height:normal;font-family:Menlo,'DejaVu Sans Mono',consolas,'Courier New',monospace\"><span style=\"font-weight: bold\"> Trainable params: </span><span style=\"color: #00af00; text-decoration-color: #00af00\">0</span> (0.00 B)\n",
       "</pre>\n"
      ],
      "text/plain": [
       "\u001b[1m Trainable params: \u001b[0m\u001b[38;5;34m0\u001b[0m (0.00 B)\n"
      ]
     },
     "metadata": {},
     "output_type": "display_data"
    },
    {
     "data": {
      "text/html": [
       "<pre style=\"white-space:pre;overflow-x:auto;line-height:normal;font-family:Menlo,'DejaVu Sans Mono',consolas,'Courier New',monospace\"><span style=\"font-weight: bold\"> Non-trainable params: </span><span style=\"color: #00af00; text-decoration-color: #00af00\">0</span> (0.00 B)\n",
       "</pre>\n"
      ],
      "text/plain": [
       "\u001b[1m Non-trainable params: \u001b[0m\u001b[38;5;34m0\u001b[0m (0.00 B)\n"
      ]
     },
     "metadata": {},
     "output_type": "display_data"
    },
    {
     "name": "stdout",
     "output_type": "stream",
     "text": [
      "Error durante el ajuste del modelo: \n",
      "All the 24 fits failed.\n",
      "It is very likely that your model is misconfigured.\n",
      "You can try to debug the error by setting error_score='raise'.\n",
      "\n",
      "Below are more details about the failures:\n",
      "--------------------------------------------------------------------------------\n",
      "4 fits failed with the following error:\n",
      "Traceback (most recent call last):\n",
      "  File \"C:\\Users\\Erick Carreño\\AppData\\Local\\Programs\\Python\\Python312\\Lib\\site-packages\\sklearn\\model_selection\\_validation.py\", line 888, in _fit_and_score\n",
      "    estimator.fit(X_train, y_train, **fit_params)\n",
      "  File \"C:\\Users\\Erick Carreño\\AppData\\Local\\Programs\\Python\\Python312\\Lib\\site-packages\\scikeras\\wrappers.py\", line 1501, in fit\n",
      "    super().fit(X=X, y=y, sample_weight=sample_weight, **kwargs)\n",
      "  File \"C:\\Users\\Erick Carreño\\AppData\\Local\\Programs\\Python\\Python312\\Lib\\site-packages\\scikeras\\wrappers.py\", line 770, in fit\n",
      "    self._fit(\n",
      "  File \"C:\\Users\\Erick Carreño\\AppData\\Local\\Programs\\Python\\Python312\\Lib\\site-packages\\scikeras\\wrappers.py\", line 936, in _fit\n",
      "    self._check_model_compatibility(y)\n",
      "  File \"C:\\Users\\Erick Carreño\\AppData\\Local\\Programs\\Python\\Python312\\Lib\\site-packages\\scikeras\\wrappers.py\", line 559, in _check_model_compatibility\n",
      "    if self.n_outputs_expected_ != len(self.model_.outputs):\n",
      "                                       ^^^^^^^^^^^^^^^^^^^\n",
      "  File \"C:\\Users\\Erick Carreño\\AppData\\Local\\Programs\\Python\\Python312\\Lib\\site-packages\\keras\\src\\models\\sequential.py\", line 292, in outputs\n",
      "    raise ValueError(\n",
      "ValueError: Sequential model 'sequential' has no defined outputs yet.\n",
      "\n",
      "--------------------------------------------------------------------------------\n",
      "4 fits failed with the following error:\n",
      "Traceback (most recent call last):\n",
      "  File \"C:\\Users\\Erick Carreño\\AppData\\Local\\Programs\\Python\\Python312\\Lib\\site-packages\\sklearn\\model_selection\\_validation.py\", line 888, in _fit_and_score\n",
      "    estimator.fit(X_train, y_train, **fit_params)\n",
      "  File \"C:\\Users\\Erick Carreño\\AppData\\Local\\Programs\\Python\\Python312\\Lib\\site-packages\\scikeras\\wrappers.py\", line 1501, in fit\n",
      "    super().fit(X=X, y=y, sample_weight=sample_weight, **kwargs)\n",
      "  File \"C:\\Users\\Erick Carreño\\AppData\\Local\\Programs\\Python\\Python312\\Lib\\site-packages\\scikeras\\wrappers.py\", line 770, in fit\n",
      "    self._fit(\n",
      "  File \"C:\\Users\\Erick Carreño\\AppData\\Local\\Programs\\Python\\Python312\\Lib\\site-packages\\scikeras\\wrappers.py\", line 936, in _fit\n",
      "    self._check_model_compatibility(y)\n",
      "  File \"C:\\Users\\Erick Carreño\\AppData\\Local\\Programs\\Python\\Python312\\Lib\\site-packages\\scikeras\\wrappers.py\", line 559, in _check_model_compatibility\n",
      "    if self.n_outputs_expected_ != len(self.model_.outputs):\n",
      "                                       ^^^^^^^^^^^^^^^^^^^\n",
      "  File \"C:\\Users\\Erick Carreño\\AppData\\Local\\Programs\\Python\\Python312\\Lib\\site-packages\\keras\\src\\models\\sequential.py\", line 292, in outputs\n",
      "    raise ValueError(\n",
      "ValueError: Sequential model 'sequential_1' has no defined outputs yet.\n",
      "\n",
      "--------------------------------------------------------------------------------\n",
      "3 fits failed with the following error:\n",
      "Traceback (most recent call last):\n",
      "  File \"C:\\Users\\Erick Carreño\\AppData\\Local\\Programs\\Python\\Python312\\Lib\\site-packages\\sklearn\\model_selection\\_validation.py\", line 888, in _fit_and_score\n",
      "    estimator.fit(X_train, y_train, **fit_params)\n",
      "  File \"C:\\Users\\Erick Carreño\\AppData\\Local\\Programs\\Python\\Python312\\Lib\\site-packages\\scikeras\\wrappers.py\", line 1501, in fit\n",
      "    super().fit(X=X, y=y, sample_weight=sample_weight, **kwargs)\n",
      "  File \"C:\\Users\\Erick Carreño\\AppData\\Local\\Programs\\Python\\Python312\\Lib\\site-packages\\scikeras\\wrappers.py\", line 770, in fit\n",
      "    self._fit(\n",
      "  File \"C:\\Users\\Erick Carreño\\AppData\\Local\\Programs\\Python\\Python312\\Lib\\site-packages\\scikeras\\wrappers.py\", line 936, in _fit\n",
      "    self._check_model_compatibility(y)\n",
      "  File \"C:\\Users\\Erick Carreño\\AppData\\Local\\Programs\\Python\\Python312\\Lib\\site-packages\\scikeras\\wrappers.py\", line 559, in _check_model_compatibility\n",
      "    if self.n_outputs_expected_ != len(self.model_.outputs):\n",
      "                                       ^^^^^^^^^^^^^^^^^^^\n",
      "  File \"C:\\Users\\Erick Carreño\\AppData\\Local\\Programs\\Python\\Python312\\Lib\\site-packages\\keras\\src\\models\\sequential.py\", line 292, in outputs\n",
      "    raise ValueError(\n",
      "ValueError: Sequential model 'sequential_2' has no defined outputs yet.\n",
      "\n",
      "--------------------------------------------------------------------------------\n",
      "3 fits failed with the following error:\n",
      "Traceback (most recent call last):\n",
      "  File \"C:\\Users\\Erick Carreño\\AppData\\Local\\Programs\\Python\\Python312\\Lib\\site-packages\\sklearn\\model_selection\\_validation.py\", line 888, in _fit_and_score\n",
      "    estimator.fit(X_train, y_train, **fit_params)\n",
      "  File \"C:\\Users\\Erick Carreño\\AppData\\Local\\Programs\\Python\\Python312\\Lib\\site-packages\\scikeras\\wrappers.py\", line 1501, in fit\n",
      "    super().fit(X=X, y=y, sample_weight=sample_weight, **kwargs)\n",
      "  File \"C:\\Users\\Erick Carreño\\AppData\\Local\\Programs\\Python\\Python312\\Lib\\site-packages\\scikeras\\wrappers.py\", line 770, in fit\n",
      "    self._fit(\n",
      "  File \"C:\\Users\\Erick Carreño\\AppData\\Local\\Programs\\Python\\Python312\\Lib\\site-packages\\scikeras\\wrappers.py\", line 936, in _fit\n",
      "    self._check_model_compatibility(y)\n",
      "  File \"C:\\Users\\Erick Carreño\\AppData\\Local\\Programs\\Python\\Python312\\Lib\\site-packages\\scikeras\\wrappers.py\", line 559, in _check_model_compatibility\n",
      "    if self.n_outputs_expected_ != len(self.model_.outputs):\n",
      "                                       ^^^^^^^^^^^^^^^^^^^\n",
      "  File \"C:\\Users\\Erick Carreño\\AppData\\Local\\Programs\\Python\\Python312\\Lib\\site-packages\\keras\\src\\models\\sequential.py\", line 292, in outputs\n",
      "    raise ValueError(\n",
      "ValueError: Sequential model 'sequential_3' has no defined outputs yet.\n",
      "\n",
      "--------------------------------------------------------------------------------\n",
      "3 fits failed with the following error:\n",
      "Traceback (most recent call last):\n",
      "  File \"C:\\Users\\Erick Carreño\\AppData\\Local\\Programs\\Python\\Python312\\Lib\\site-packages\\sklearn\\model_selection\\_validation.py\", line 888, in _fit_and_score\n",
      "    estimator.fit(X_train, y_train, **fit_params)\n",
      "  File \"C:\\Users\\Erick Carreño\\AppData\\Local\\Programs\\Python\\Python312\\Lib\\site-packages\\scikeras\\wrappers.py\", line 1501, in fit\n",
      "    super().fit(X=X, y=y, sample_weight=sample_weight, **kwargs)\n",
      "  File \"C:\\Users\\Erick Carreño\\AppData\\Local\\Programs\\Python\\Python312\\Lib\\site-packages\\scikeras\\wrappers.py\", line 770, in fit\n",
      "    self._fit(\n",
      "  File \"C:\\Users\\Erick Carreño\\AppData\\Local\\Programs\\Python\\Python312\\Lib\\site-packages\\scikeras\\wrappers.py\", line 936, in _fit\n",
      "    self._check_model_compatibility(y)\n",
      "  File \"C:\\Users\\Erick Carreño\\AppData\\Local\\Programs\\Python\\Python312\\Lib\\site-packages\\scikeras\\wrappers.py\", line 559, in _check_model_compatibility\n",
      "    if self.n_outputs_expected_ != len(self.model_.outputs):\n",
      "                                       ^^^^^^^^^^^^^^^^^^^\n",
      "  File \"C:\\Users\\Erick Carreño\\AppData\\Local\\Programs\\Python\\Python312\\Lib\\site-packages\\keras\\src\\models\\sequential.py\", line 292, in outputs\n",
      "    raise ValueError(\n",
      "ValueError: Sequential model 'sequential_4' has no defined outputs yet.\n",
      "\n",
      "--------------------------------------------------------------------------------\n",
      "3 fits failed with the following error:\n",
      "Traceback (most recent call last):\n",
      "  File \"C:\\Users\\Erick Carreño\\AppData\\Local\\Programs\\Python\\Python312\\Lib\\site-packages\\sklearn\\model_selection\\_validation.py\", line 888, in _fit_and_score\n",
      "    estimator.fit(X_train, y_train, **fit_params)\n",
      "  File \"C:\\Users\\Erick Carreño\\AppData\\Local\\Programs\\Python\\Python312\\Lib\\site-packages\\scikeras\\wrappers.py\", line 1501, in fit\n",
      "    super().fit(X=X, y=y, sample_weight=sample_weight, **kwargs)\n",
      "  File \"C:\\Users\\Erick Carreño\\AppData\\Local\\Programs\\Python\\Python312\\Lib\\site-packages\\scikeras\\wrappers.py\", line 770, in fit\n",
      "    self._fit(\n",
      "  File \"C:\\Users\\Erick Carreño\\AppData\\Local\\Programs\\Python\\Python312\\Lib\\site-packages\\scikeras\\wrappers.py\", line 936, in _fit\n",
      "    self._check_model_compatibility(y)\n",
      "  File \"C:\\Users\\Erick Carreño\\AppData\\Local\\Programs\\Python\\Python312\\Lib\\site-packages\\scikeras\\wrappers.py\", line 559, in _check_model_compatibility\n",
      "    if self.n_outputs_expected_ != len(self.model_.outputs):\n",
      "                                       ^^^^^^^^^^^^^^^^^^^\n",
      "  File \"C:\\Users\\Erick Carreño\\AppData\\Local\\Programs\\Python\\Python312\\Lib\\site-packages\\keras\\src\\models\\sequential.py\", line 292, in outputs\n",
      "    raise ValueError(\n",
      "ValueError: Sequential model 'sequential_5' has no defined outputs yet.\n",
      "\n",
      "--------------------------------------------------------------------------------\n",
      "3 fits failed with the following error:\n",
      "Traceback (most recent call last):\n",
      "  File \"C:\\Users\\Erick Carreño\\AppData\\Local\\Programs\\Python\\Python312\\Lib\\site-packages\\sklearn\\model_selection\\_validation.py\", line 888, in _fit_and_score\n",
      "    estimator.fit(X_train, y_train, **fit_params)\n",
      "  File \"C:\\Users\\Erick Carreño\\AppData\\Local\\Programs\\Python\\Python312\\Lib\\site-packages\\scikeras\\wrappers.py\", line 1501, in fit\n",
      "    super().fit(X=X, y=y, sample_weight=sample_weight, **kwargs)\n",
      "  File \"C:\\Users\\Erick Carreño\\AppData\\Local\\Programs\\Python\\Python312\\Lib\\site-packages\\scikeras\\wrappers.py\", line 770, in fit\n",
      "    self._fit(\n",
      "  File \"C:\\Users\\Erick Carreño\\AppData\\Local\\Programs\\Python\\Python312\\Lib\\site-packages\\scikeras\\wrappers.py\", line 936, in _fit\n",
      "    self._check_model_compatibility(y)\n",
      "  File \"C:\\Users\\Erick Carreño\\AppData\\Local\\Programs\\Python\\Python312\\Lib\\site-packages\\scikeras\\wrappers.py\", line 559, in _check_model_compatibility\n",
      "    if self.n_outputs_expected_ != len(self.model_.outputs):\n",
      "                                       ^^^^^^^^^^^^^^^^^^^\n",
      "  File \"C:\\Users\\Erick Carreño\\AppData\\Local\\Programs\\Python\\Python312\\Lib\\site-packages\\keras\\src\\models\\sequential.py\", line 292, in outputs\n",
      "    raise ValueError(\n",
      "ValueError: Sequential model 'sequential_6' has no defined outputs yet.\n",
      "\n",
      "--------------------------------------------------------------------------------\n",
      "1 fits failed with the following error:\n",
      "Traceback (most recent call last):\n",
      "  File \"C:\\Users\\Erick Carreño\\AppData\\Local\\Programs\\Python\\Python312\\Lib\\site-packages\\sklearn\\model_selection\\_validation.py\", line 888, in _fit_and_score\n",
      "    estimator.fit(X_train, y_train, **fit_params)\n",
      "  File \"C:\\Users\\Erick Carreño\\AppData\\Local\\Programs\\Python\\Python312\\Lib\\site-packages\\scikeras\\wrappers.py\", line 1501, in fit\n",
      "    super().fit(X=X, y=y, sample_weight=sample_weight, **kwargs)\n",
      "  File \"C:\\Users\\Erick Carreño\\AppData\\Local\\Programs\\Python\\Python312\\Lib\\site-packages\\scikeras\\wrappers.py\", line 770, in fit\n",
      "    self._fit(\n",
      "  File \"C:\\Users\\Erick Carreño\\AppData\\Local\\Programs\\Python\\Python312\\Lib\\site-packages\\scikeras\\wrappers.py\", line 936, in _fit\n",
      "    self._check_model_compatibility(y)\n",
      "  File \"C:\\Users\\Erick Carreño\\AppData\\Local\\Programs\\Python\\Python312\\Lib\\site-packages\\scikeras\\wrappers.py\", line 559, in _check_model_compatibility\n",
      "    if self.n_outputs_expected_ != len(self.model_.outputs):\n",
      "                                       ^^^^^^^^^^^^^^^^^^^\n",
      "  File \"C:\\Users\\Erick Carreño\\AppData\\Local\\Programs\\Python\\Python312\\Lib\\site-packages\\keras\\src\\models\\sequential.py\", line 292, in outputs\n",
      "    raise ValueError(\n",
      "ValueError: Sequential model 'sequential_7' has no defined outputs yet.\n",
      "\n"
     ]
    },
    {
     "ename": "ValueError",
     "evalue": "\nAll the 24 fits failed.\nIt is very likely that your model is misconfigured.\nYou can try to debug the error by setting error_score='raise'.\n\nBelow are more details about the failures:\n--------------------------------------------------------------------------------\n4 fits failed with the following error:\nTraceback (most recent call last):\n  File \"C:\\Users\\Erick Carreño\\AppData\\Local\\Programs\\Python\\Python312\\Lib\\site-packages\\sklearn\\model_selection\\_validation.py\", line 888, in _fit_and_score\n    estimator.fit(X_train, y_train, **fit_params)\n  File \"C:\\Users\\Erick Carreño\\AppData\\Local\\Programs\\Python\\Python312\\Lib\\site-packages\\scikeras\\wrappers.py\", line 1501, in fit\n    super().fit(X=X, y=y, sample_weight=sample_weight, **kwargs)\n  File \"C:\\Users\\Erick Carreño\\AppData\\Local\\Programs\\Python\\Python312\\Lib\\site-packages\\scikeras\\wrappers.py\", line 770, in fit\n    self._fit(\n  File \"C:\\Users\\Erick Carreño\\AppData\\Local\\Programs\\Python\\Python312\\Lib\\site-packages\\scikeras\\wrappers.py\", line 936, in _fit\n    self._check_model_compatibility(y)\n  File \"C:\\Users\\Erick Carreño\\AppData\\Local\\Programs\\Python\\Python312\\Lib\\site-packages\\scikeras\\wrappers.py\", line 559, in _check_model_compatibility\n    if self.n_outputs_expected_ != len(self.model_.outputs):\n                                       ^^^^^^^^^^^^^^^^^^^\n  File \"C:\\Users\\Erick Carreño\\AppData\\Local\\Programs\\Python\\Python312\\Lib\\site-packages\\keras\\src\\models\\sequential.py\", line 292, in outputs\n    raise ValueError(\nValueError: Sequential model 'sequential' has no defined outputs yet.\n\n--------------------------------------------------------------------------------\n4 fits failed with the following error:\nTraceback (most recent call last):\n  File \"C:\\Users\\Erick Carreño\\AppData\\Local\\Programs\\Python\\Python312\\Lib\\site-packages\\sklearn\\model_selection\\_validation.py\", line 888, in _fit_and_score\n    estimator.fit(X_train, y_train, **fit_params)\n  File \"C:\\Users\\Erick Carreño\\AppData\\Local\\Programs\\Python\\Python312\\Lib\\site-packages\\scikeras\\wrappers.py\", line 1501, in fit\n    super().fit(X=X, y=y, sample_weight=sample_weight, **kwargs)\n  File \"C:\\Users\\Erick Carreño\\AppData\\Local\\Programs\\Python\\Python312\\Lib\\site-packages\\scikeras\\wrappers.py\", line 770, in fit\n    self._fit(\n  File \"C:\\Users\\Erick Carreño\\AppData\\Local\\Programs\\Python\\Python312\\Lib\\site-packages\\scikeras\\wrappers.py\", line 936, in _fit\n    self._check_model_compatibility(y)\n  File \"C:\\Users\\Erick Carreño\\AppData\\Local\\Programs\\Python\\Python312\\Lib\\site-packages\\scikeras\\wrappers.py\", line 559, in _check_model_compatibility\n    if self.n_outputs_expected_ != len(self.model_.outputs):\n                                       ^^^^^^^^^^^^^^^^^^^\n  File \"C:\\Users\\Erick Carreño\\AppData\\Local\\Programs\\Python\\Python312\\Lib\\site-packages\\keras\\src\\models\\sequential.py\", line 292, in outputs\n    raise ValueError(\nValueError: Sequential model 'sequential_1' has no defined outputs yet.\n\n--------------------------------------------------------------------------------\n3 fits failed with the following error:\nTraceback (most recent call last):\n  File \"C:\\Users\\Erick Carreño\\AppData\\Local\\Programs\\Python\\Python312\\Lib\\site-packages\\sklearn\\model_selection\\_validation.py\", line 888, in _fit_and_score\n    estimator.fit(X_train, y_train, **fit_params)\n  File \"C:\\Users\\Erick Carreño\\AppData\\Local\\Programs\\Python\\Python312\\Lib\\site-packages\\scikeras\\wrappers.py\", line 1501, in fit\n    super().fit(X=X, y=y, sample_weight=sample_weight, **kwargs)\n  File \"C:\\Users\\Erick Carreño\\AppData\\Local\\Programs\\Python\\Python312\\Lib\\site-packages\\scikeras\\wrappers.py\", line 770, in fit\n    self._fit(\n  File \"C:\\Users\\Erick Carreño\\AppData\\Local\\Programs\\Python\\Python312\\Lib\\site-packages\\scikeras\\wrappers.py\", line 936, in _fit\n    self._check_model_compatibility(y)\n  File \"C:\\Users\\Erick Carreño\\AppData\\Local\\Programs\\Python\\Python312\\Lib\\site-packages\\scikeras\\wrappers.py\", line 559, in _check_model_compatibility\n    if self.n_outputs_expected_ != len(self.model_.outputs):\n                                       ^^^^^^^^^^^^^^^^^^^\n  File \"C:\\Users\\Erick Carreño\\AppData\\Local\\Programs\\Python\\Python312\\Lib\\site-packages\\keras\\src\\models\\sequential.py\", line 292, in outputs\n    raise ValueError(\nValueError: Sequential model 'sequential_2' has no defined outputs yet.\n\n--------------------------------------------------------------------------------\n3 fits failed with the following error:\nTraceback (most recent call last):\n  File \"C:\\Users\\Erick Carreño\\AppData\\Local\\Programs\\Python\\Python312\\Lib\\site-packages\\sklearn\\model_selection\\_validation.py\", line 888, in _fit_and_score\n    estimator.fit(X_train, y_train, **fit_params)\n  File \"C:\\Users\\Erick Carreño\\AppData\\Local\\Programs\\Python\\Python312\\Lib\\site-packages\\scikeras\\wrappers.py\", line 1501, in fit\n    super().fit(X=X, y=y, sample_weight=sample_weight, **kwargs)\n  File \"C:\\Users\\Erick Carreño\\AppData\\Local\\Programs\\Python\\Python312\\Lib\\site-packages\\scikeras\\wrappers.py\", line 770, in fit\n    self._fit(\n  File \"C:\\Users\\Erick Carreño\\AppData\\Local\\Programs\\Python\\Python312\\Lib\\site-packages\\scikeras\\wrappers.py\", line 936, in _fit\n    self._check_model_compatibility(y)\n  File \"C:\\Users\\Erick Carreño\\AppData\\Local\\Programs\\Python\\Python312\\Lib\\site-packages\\scikeras\\wrappers.py\", line 559, in _check_model_compatibility\n    if self.n_outputs_expected_ != len(self.model_.outputs):\n                                       ^^^^^^^^^^^^^^^^^^^\n  File \"C:\\Users\\Erick Carreño\\AppData\\Local\\Programs\\Python\\Python312\\Lib\\site-packages\\keras\\src\\models\\sequential.py\", line 292, in outputs\n    raise ValueError(\nValueError: Sequential model 'sequential_3' has no defined outputs yet.\n\n--------------------------------------------------------------------------------\n3 fits failed with the following error:\nTraceback (most recent call last):\n  File \"C:\\Users\\Erick Carreño\\AppData\\Local\\Programs\\Python\\Python312\\Lib\\site-packages\\sklearn\\model_selection\\_validation.py\", line 888, in _fit_and_score\n    estimator.fit(X_train, y_train, **fit_params)\n  File \"C:\\Users\\Erick Carreño\\AppData\\Local\\Programs\\Python\\Python312\\Lib\\site-packages\\scikeras\\wrappers.py\", line 1501, in fit\n    super().fit(X=X, y=y, sample_weight=sample_weight, **kwargs)\n  File \"C:\\Users\\Erick Carreño\\AppData\\Local\\Programs\\Python\\Python312\\Lib\\site-packages\\scikeras\\wrappers.py\", line 770, in fit\n    self._fit(\n  File \"C:\\Users\\Erick Carreño\\AppData\\Local\\Programs\\Python\\Python312\\Lib\\site-packages\\scikeras\\wrappers.py\", line 936, in _fit\n    self._check_model_compatibility(y)\n  File \"C:\\Users\\Erick Carreño\\AppData\\Local\\Programs\\Python\\Python312\\Lib\\site-packages\\scikeras\\wrappers.py\", line 559, in _check_model_compatibility\n    if self.n_outputs_expected_ != len(self.model_.outputs):\n                                       ^^^^^^^^^^^^^^^^^^^\n  File \"C:\\Users\\Erick Carreño\\AppData\\Local\\Programs\\Python\\Python312\\Lib\\site-packages\\keras\\src\\models\\sequential.py\", line 292, in outputs\n    raise ValueError(\nValueError: Sequential model 'sequential_4' has no defined outputs yet.\n\n--------------------------------------------------------------------------------\n3 fits failed with the following error:\nTraceback (most recent call last):\n  File \"C:\\Users\\Erick Carreño\\AppData\\Local\\Programs\\Python\\Python312\\Lib\\site-packages\\sklearn\\model_selection\\_validation.py\", line 888, in _fit_and_score\n    estimator.fit(X_train, y_train, **fit_params)\n  File \"C:\\Users\\Erick Carreño\\AppData\\Local\\Programs\\Python\\Python312\\Lib\\site-packages\\scikeras\\wrappers.py\", line 1501, in fit\n    super().fit(X=X, y=y, sample_weight=sample_weight, **kwargs)\n  File \"C:\\Users\\Erick Carreño\\AppData\\Local\\Programs\\Python\\Python312\\Lib\\site-packages\\scikeras\\wrappers.py\", line 770, in fit\n    self._fit(\n  File \"C:\\Users\\Erick Carreño\\AppData\\Local\\Programs\\Python\\Python312\\Lib\\site-packages\\scikeras\\wrappers.py\", line 936, in _fit\n    self._check_model_compatibility(y)\n  File \"C:\\Users\\Erick Carreño\\AppData\\Local\\Programs\\Python\\Python312\\Lib\\site-packages\\scikeras\\wrappers.py\", line 559, in _check_model_compatibility\n    if self.n_outputs_expected_ != len(self.model_.outputs):\n                                       ^^^^^^^^^^^^^^^^^^^\n  File \"C:\\Users\\Erick Carreño\\AppData\\Local\\Programs\\Python\\Python312\\Lib\\site-packages\\keras\\src\\models\\sequential.py\", line 292, in outputs\n    raise ValueError(\nValueError: Sequential model 'sequential_5' has no defined outputs yet.\n\n--------------------------------------------------------------------------------\n3 fits failed with the following error:\nTraceback (most recent call last):\n  File \"C:\\Users\\Erick Carreño\\AppData\\Local\\Programs\\Python\\Python312\\Lib\\site-packages\\sklearn\\model_selection\\_validation.py\", line 888, in _fit_and_score\n    estimator.fit(X_train, y_train, **fit_params)\n  File \"C:\\Users\\Erick Carreño\\AppData\\Local\\Programs\\Python\\Python312\\Lib\\site-packages\\scikeras\\wrappers.py\", line 1501, in fit\n    super().fit(X=X, y=y, sample_weight=sample_weight, **kwargs)\n  File \"C:\\Users\\Erick Carreño\\AppData\\Local\\Programs\\Python\\Python312\\Lib\\site-packages\\scikeras\\wrappers.py\", line 770, in fit\n    self._fit(\n  File \"C:\\Users\\Erick Carreño\\AppData\\Local\\Programs\\Python\\Python312\\Lib\\site-packages\\scikeras\\wrappers.py\", line 936, in _fit\n    self._check_model_compatibility(y)\n  File \"C:\\Users\\Erick Carreño\\AppData\\Local\\Programs\\Python\\Python312\\Lib\\site-packages\\scikeras\\wrappers.py\", line 559, in _check_model_compatibility\n    if self.n_outputs_expected_ != len(self.model_.outputs):\n                                       ^^^^^^^^^^^^^^^^^^^\n  File \"C:\\Users\\Erick Carreño\\AppData\\Local\\Programs\\Python\\Python312\\Lib\\site-packages\\keras\\src\\models\\sequential.py\", line 292, in outputs\n    raise ValueError(\nValueError: Sequential model 'sequential_6' has no defined outputs yet.\n\n--------------------------------------------------------------------------------\n1 fits failed with the following error:\nTraceback (most recent call last):\n  File \"C:\\Users\\Erick Carreño\\AppData\\Local\\Programs\\Python\\Python312\\Lib\\site-packages\\sklearn\\model_selection\\_validation.py\", line 888, in _fit_and_score\n    estimator.fit(X_train, y_train, **fit_params)\n  File \"C:\\Users\\Erick Carreño\\AppData\\Local\\Programs\\Python\\Python312\\Lib\\site-packages\\scikeras\\wrappers.py\", line 1501, in fit\n    super().fit(X=X, y=y, sample_weight=sample_weight, **kwargs)\n  File \"C:\\Users\\Erick Carreño\\AppData\\Local\\Programs\\Python\\Python312\\Lib\\site-packages\\scikeras\\wrappers.py\", line 770, in fit\n    self._fit(\n  File \"C:\\Users\\Erick Carreño\\AppData\\Local\\Programs\\Python\\Python312\\Lib\\site-packages\\scikeras\\wrappers.py\", line 936, in _fit\n    self._check_model_compatibility(y)\n  File \"C:\\Users\\Erick Carreño\\AppData\\Local\\Programs\\Python\\Python312\\Lib\\site-packages\\scikeras\\wrappers.py\", line 559, in _check_model_compatibility\n    if self.n_outputs_expected_ != len(self.model_.outputs):\n                                       ^^^^^^^^^^^^^^^^^^^\n  File \"C:\\Users\\Erick Carreño\\AppData\\Local\\Programs\\Python\\Python312\\Lib\\site-packages\\keras\\src\\models\\sequential.py\", line 292, in outputs\n    raise ValueError(\nValueError: Sequential model 'sequential_7' has no defined outputs yet.\n",
     "output_type": "error",
     "traceback": [
      "\u001b[1;31m---------------------------------------------------------------------------\u001b[0m",
      "\u001b[1;31mValueError\u001b[0m                                Traceback (most recent call last)",
      "Cell \u001b[1;32mIn[77], line 44\u001b[0m\n\u001b[0;32m     41\u001b[0m grid \u001b[38;5;241m=\u001b[39m GridSearchCV(estimator\u001b[38;5;241m=\u001b[39mmodel, param_grid\u001b[38;5;241m=\u001b[39mparam_grid, n_jobs\u001b[38;5;241m=\u001b[39m\u001b[38;5;241m-\u001b[39m\u001b[38;5;241m1\u001b[39m, cv\u001b[38;5;241m=\u001b[39m\u001b[38;5;241m3\u001b[39m)\n\u001b[0;32m     43\u001b[0m \u001b[38;5;28;01mtry\u001b[39;00m:\n\u001b[1;32m---> 44\u001b[0m     grid_result \u001b[38;5;241m=\u001b[39m \u001b[43mgrid\u001b[49m\u001b[38;5;241;43m.\u001b[39;49m\u001b[43mfit\u001b[49m\u001b[43m(\u001b[49m\u001b[43mX_train\u001b[49m\u001b[43m,\u001b[49m\u001b[43m \u001b[49m\u001b[43my_train\u001b[49m\u001b[43m)\u001b[49m\n\u001b[0;32m     45\u001b[0m \u001b[38;5;28;01mexcept\u001b[39;00m \u001b[38;5;167;01mValueError\u001b[39;00m \u001b[38;5;28;01mas\u001b[39;00m e:\n\u001b[0;32m     46\u001b[0m     \u001b[38;5;28mprint\u001b[39m(\u001b[38;5;124mf\u001b[39m\u001b[38;5;124m\"\u001b[39m\u001b[38;5;124mError durante el ajuste del modelo: \u001b[39m\u001b[38;5;132;01m{\u001b[39;00me\u001b[38;5;132;01m}\u001b[39;00m\u001b[38;5;124m\"\u001b[39m)\n",
      "File \u001b[1;32m~\\AppData\\Local\\Programs\\Python\\Python312\\Lib\\site-packages\\sklearn\\base.py:1473\u001b[0m, in \u001b[0;36m_fit_context.<locals>.decorator.<locals>.wrapper\u001b[1;34m(estimator, *args, **kwargs)\u001b[0m\n\u001b[0;32m   1466\u001b[0m     estimator\u001b[38;5;241m.\u001b[39m_validate_params()\n\u001b[0;32m   1468\u001b[0m \u001b[38;5;28;01mwith\u001b[39;00m config_context(\n\u001b[0;32m   1469\u001b[0m     skip_parameter_validation\u001b[38;5;241m=\u001b[39m(\n\u001b[0;32m   1470\u001b[0m         prefer_skip_nested_validation \u001b[38;5;129;01mor\u001b[39;00m global_skip_validation\n\u001b[0;32m   1471\u001b[0m     )\n\u001b[0;32m   1472\u001b[0m ):\n\u001b[1;32m-> 1473\u001b[0m     \u001b[38;5;28;01mreturn\u001b[39;00m \u001b[43mfit_method\u001b[49m\u001b[43m(\u001b[49m\u001b[43mestimator\u001b[49m\u001b[43m,\u001b[49m\u001b[43m \u001b[49m\u001b[38;5;241;43m*\u001b[39;49m\u001b[43margs\u001b[49m\u001b[43m,\u001b[49m\u001b[43m \u001b[49m\u001b[38;5;241;43m*\u001b[39;49m\u001b[38;5;241;43m*\u001b[39;49m\u001b[43mkwargs\u001b[49m\u001b[43m)\u001b[49m\n",
      "File \u001b[1;32m~\\AppData\\Local\\Programs\\Python\\Python312\\Lib\\site-packages\\sklearn\\model_selection\\_search.py:968\u001b[0m, in \u001b[0;36mBaseSearchCV.fit\u001b[1;34m(self, X, y, **params)\u001b[0m\n\u001b[0;32m    962\u001b[0m     results \u001b[38;5;241m=\u001b[39m \u001b[38;5;28mself\u001b[39m\u001b[38;5;241m.\u001b[39m_format_results(\n\u001b[0;32m    963\u001b[0m         all_candidate_params, n_splits, all_out, all_more_results\n\u001b[0;32m    964\u001b[0m     )\n\u001b[0;32m    966\u001b[0m     \u001b[38;5;28;01mreturn\u001b[39;00m results\n\u001b[1;32m--> 968\u001b[0m \u001b[38;5;28;43mself\u001b[39;49m\u001b[38;5;241;43m.\u001b[39;49m\u001b[43m_run_search\u001b[49m\u001b[43m(\u001b[49m\u001b[43mevaluate_candidates\u001b[49m\u001b[43m)\u001b[49m\n\u001b[0;32m    970\u001b[0m \u001b[38;5;66;03m# multimetric is determined here because in the case of a callable\u001b[39;00m\n\u001b[0;32m    971\u001b[0m \u001b[38;5;66;03m# self.scoring the return type is only known after calling\u001b[39;00m\n\u001b[0;32m    972\u001b[0m first_test_score \u001b[38;5;241m=\u001b[39m all_out[\u001b[38;5;241m0\u001b[39m][\u001b[38;5;124m\"\u001b[39m\u001b[38;5;124mtest_scores\u001b[39m\u001b[38;5;124m\"\u001b[39m]\n",
      "File \u001b[1;32m~\\AppData\\Local\\Programs\\Python\\Python312\\Lib\\site-packages\\sklearn\\model_selection\\_search.py:1543\u001b[0m, in \u001b[0;36mGridSearchCV._run_search\u001b[1;34m(self, evaluate_candidates)\u001b[0m\n\u001b[0;32m   1541\u001b[0m \u001b[38;5;28;01mdef\u001b[39;00m \u001b[38;5;21m_run_search\u001b[39m(\u001b[38;5;28mself\u001b[39m, evaluate_candidates):\n\u001b[0;32m   1542\u001b[0m \u001b[38;5;250m    \u001b[39m\u001b[38;5;124;03m\"\"\"Search all candidates in param_grid\"\"\"\u001b[39;00m\n\u001b[1;32m-> 1543\u001b[0m     \u001b[43mevaluate_candidates\u001b[49m\u001b[43m(\u001b[49m\u001b[43mParameterGrid\u001b[49m\u001b[43m(\u001b[49m\u001b[38;5;28;43mself\u001b[39;49m\u001b[38;5;241;43m.\u001b[39;49m\u001b[43mparam_grid\u001b[49m\u001b[43m)\u001b[49m\u001b[43m)\u001b[49m\n",
      "File \u001b[1;32m~\\AppData\\Local\\Programs\\Python\\Python312\\Lib\\site-packages\\sklearn\\model_selection\\_search.py:945\u001b[0m, in \u001b[0;36mBaseSearchCV.fit.<locals>.evaluate_candidates\u001b[1;34m(candidate_params, cv, more_results)\u001b[0m\n\u001b[0;32m    938\u001b[0m \u001b[38;5;28;01melif\u001b[39;00m \u001b[38;5;28mlen\u001b[39m(out) \u001b[38;5;241m!=\u001b[39m n_candidates \u001b[38;5;241m*\u001b[39m n_splits:\n\u001b[0;32m    939\u001b[0m     \u001b[38;5;28;01mraise\u001b[39;00m \u001b[38;5;167;01mValueError\u001b[39;00m(\n\u001b[0;32m    940\u001b[0m         \u001b[38;5;124m\"\u001b[39m\u001b[38;5;124mcv.split and cv.get_n_splits returned \u001b[39m\u001b[38;5;124m\"\u001b[39m\n\u001b[0;32m    941\u001b[0m         \u001b[38;5;124m\"\u001b[39m\u001b[38;5;124minconsistent results. Expected \u001b[39m\u001b[38;5;132;01m{}\u001b[39;00m\u001b[38;5;124m \u001b[39m\u001b[38;5;124m\"\u001b[39m\n\u001b[0;32m    942\u001b[0m         \u001b[38;5;124m\"\u001b[39m\u001b[38;5;124msplits, got \u001b[39m\u001b[38;5;132;01m{}\u001b[39;00m\u001b[38;5;124m\"\u001b[39m\u001b[38;5;241m.\u001b[39mformat(n_splits, \u001b[38;5;28mlen\u001b[39m(out) \u001b[38;5;241m/\u001b[39m\u001b[38;5;241m/\u001b[39m n_candidates)\n\u001b[0;32m    943\u001b[0m     )\n\u001b[1;32m--> 945\u001b[0m \u001b[43m_warn_or_raise_about_fit_failures\u001b[49m\u001b[43m(\u001b[49m\u001b[43mout\u001b[49m\u001b[43m,\u001b[49m\u001b[43m \u001b[49m\u001b[38;5;28;43mself\u001b[39;49m\u001b[38;5;241;43m.\u001b[39;49m\u001b[43merror_score\u001b[49m\u001b[43m)\u001b[49m\n\u001b[0;32m    947\u001b[0m \u001b[38;5;66;03m# For callable self.scoring, the return type is only know after\u001b[39;00m\n\u001b[0;32m    948\u001b[0m \u001b[38;5;66;03m# calling. If the return type is a dictionary, the error scores\u001b[39;00m\n\u001b[0;32m    949\u001b[0m \u001b[38;5;66;03m# can now be inserted with the correct key. The type checking\u001b[39;00m\n\u001b[0;32m    950\u001b[0m \u001b[38;5;66;03m# of out will be done in `_insert_error_scores`.\u001b[39;00m\n\u001b[0;32m    951\u001b[0m \u001b[38;5;28;01mif\u001b[39;00m \u001b[38;5;28mcallable\u001b[39m(\u001b[38;5;28mself\u001b[39m\u001b[38;5;241m.\u001b[39mscoring):\n",
      "File \u001b[1;32m~\\AppData\\Local\\Programs\\Python\\Python312\\Lib\\site-packages\\sklearn\\model_selection\\_validation.py:529\u001b[0m, in \u001b[0;36m_warn_or_raise_about_fit_failures\u001b[1;34m(results, error_score)\u001b[0m\n\u001b[0;32m    522\u001b[0m \u001b[38;5;28;01mif\u001b[39;00m num_failed_fits \u001b[38;5;241m==\u001b[39m num_fits:\n\u001b[0;32m    523\u001b[0m     all_fits_failed_message \u001b[38;5;241m=\u001b[39m (\n\u001b[0;32m    524\u001b[0m         \u001b[38;5;124mf\u001b[39m\u001b[38;5;124m\"\u001b[39m\u001b[38;5;130;01m\\n\u001b[39;00m\u001b[38;5;124mAll the \u001b[39m\u001b[38;5;132;01m{\u001b[39;00mnum_fits\u001b[38;5;132;01m}\u001b[39;00m\u001b[38;5;124m fits failed.\u001b[39m\u001b[38;5;130;01m\\n\u001b[39;00m\u001b[38;5;124m\"\u001b[39m\n\u001b[0;32m    525\u001b[0m         \u001b[38;5;124m\"\u001b[39m\u001b[38;5;124mIt is very likely that your model is misconfigured.\u001b[39m\u001b[38;5;130;01m\\n\u001b[39;00m\u001b[38;5;124m\"\u001b[39m\n\u001b[0;32m    526\u001b[0m         \u001b[38;5;124m\"\u001b[39m\u001b[38;5;124mYou can try to debug the error by setting error_score=\u001b[39m\u001b[38;5;124m'\u001b[39m\u001b[38;5;124mraise\u001b[39m\u001b[38;5;124m'\u001b[39m\u001b[38;5;124m.\u001b[39m\u001b[38;5;130;01m\\n\u001b[39;00m\u001b[38;5;130;01m\\n\u001b[39;00m\u001b[38;5;124m\"\u001b[39m\n\u001b[0;32m    527\u001b[0m         \u001b[38;5;124mf\u001b[39m\u001b[38;5;124m\"\u001b[39m\u001b[38;5;124mBelow are more details about the failures:\u001b[39m\u001b[38;5;130;01m\\n\u001b[39;00m\u001b[38;5;132;01m{\u001b[39;00mfit_errors_summary\u001b[38;5;132;01m}\u001b[39;00m\u001b[38;5;124m\"\u001b[39m\n\u001b[0;32m    528\u001b[0m     )\n\u001b[1;32m--> 529\u001b[0m     \u001b[38;5;28;01mraise\u001b[39;00m \u001b[38;5;167;01mValueError\u001b[39;00m(all_fits_failed_message)\n\u001b[0;32m    531\u001b[0m \u001b[38;5;28;01melse\u001b[39;00m:\n\u001b[0;32m    532\u001b[0m     some_fits_failed_message \u001b[38;5;241m=\u001b[39m (\n\u001b[0;32m    533\u001b[0m         \u001b[38;5;124mf\u001b[39m\u001b[38;5;124m\"\u001b[39m\u001b[38;5;130;01m\\n\u001b[39;00m\u001b[38;5;132;01m{\u001b[39;00mnum_failed_fits\u001b[38;5;132;01m}\u001b[39;00m\u001b[38;5;124m fits failed out of a total of \u001b[39m\u001b[38;5;132;01m{\u001b[39;00mnum_fits\u001b[38;5;132;01m}\u001b[39;00m\u001b[38;5;124m.\u001b[39m\u001b[38;5;130;01m\\n\u001b[39;00m\u001b[38;5;124m\"\u001b[39m\n\u001b[0;32m    534\u001b[0m         \u001b[38;5;124m\"\u001b[39m\u001b[38;5;124mThe score on these train-test partitions for these parameters\u001b[39m\u001b[38;5;124m\"\u001b[39m\n\u001b[1;32m   (...)\u001b[0m\n\u001b[0;32m    538\u001b[0m         \u001b[38;5;124mf\u001b[39m\u001b[38;5;124m\"\u001b[39m\u001b[38;5;124mBelow are more details about the failures:\u001b[39m\u001b[38;5;130;01m\\n\u001b[39;00m\u001b[38;5;132;01m{\u001b[39;00mfit_errors_summary\u001b[38;5;132;01m}\u001b[39;00m\u001b[38;5;124m\"\u001b[39m\n\u001b[0;32m    539\u001b[0m     )\n",
      "\u001b[1;31mValueError\u001b[0m: \nAll the 24 fits failed.\nIt is very likely that your model is misconfigured.\nYou can try to debug the error by setting error_score='raise'.\n\nBelow are more details about the failures:\n--------------------------------------------------------------------------------\n4 fits failed with the following error:\nTraceback (most recent call last):\n  File \"C:\\Users\\Erick Carreño\\AppData\\Local\\Programs\\Python\\Python312\\Lib\\site-packages\\sklearn\\model_selection\\_validation.py\", line 888, in _fit_and_score\n    estimator.fit(X_train, y_train, **fit_params)\n  File \"C:\\Users\\Erick Carreño\\AppData\\Local\\Programs\\Python\\Python312\\Lib\\site-packages\\scikeras\\wrappers.py\", line 1501, in fit\n    super().fit(X=X, y=y, sample_weight=sample_weight, **kwargs)\n  File \"C:\\Users\\Erick Carreño\\AppData\\Local\\Programs\\Python\\Python312\\Lib\\site-packages\\scikeras\\wrappers.py\", line 770, in fit\n    self._fit(\n  File \"C:\\Users\\Erick Carreño\\AppData\\Local\\Programs\\Python\\Python312\\Lib\\site-packages\\scikeras\\wrappers.py\", line 936, in _fit\n    self._check_model_compatibility(y)\n  File \"C:\\Users\\Erick Carreño\\AppData\\Local\\Programs\\Python\\Python312\\Lib\\site-packages\\scikeras\\wrappers.py\", line 559, in _check_model_compatibility\n    if self.n_outputs_expected_ != len(self.model_.outputs):\n                                       ^^^^^^^^^^^^^^^^^^^\n  File \"C:\\Users\\Erick Carreño\\AppData\\Local\\Programs\\Python\\Python312\\Lib\\site-packages\\keras\\src\\models\\sequential.py\", line 292, in outputs\n    raise ValueError(\nValueError: Sequential model 'sequential' has no defined outputs yet.\n\n--------------------------------------------------------------------------------\n4 fits failed with the following error:\nTraceback (most recent call last):\n  File \"C:\\Users\\Erick Carreño\\AppData\\Local\\Programs\\Python\\Python312\\Lib\\site-packages\\sklearn\\model_selection\\_validation.py\", line 888, in _fit_and_score\n    estimator.fit(X_train, y_train, **fit_params)\n  File \"C:\\Users\\Erick Carreño\\AppData\\Local\\Programs\\Python\\Python312\\Lib\\site-packages\\scikeras\\wrappers.py\", line 1501, in fit\n    super().fit(X=X, y=y, sample_weight=sample_weight, **kwargs)\n  File \"C:\\Users\\Erick Carreño\\AppData\\Local\\Programs\\Python\\Python312\\Lib\\site-packages\\scikeras\\wrappers.py\", line 770, in fit\n    self._fit(\n  File \"C:\\Users\\Erick Carreño\\AppData\\Local\\Programs\\Python\\Python312\\Lib\\site-packages\\scikeras\\wrappers.py\", line 936, in _fit\n    self._check_model_compatibility(y)\n  File \"C:\\Users\\Erick Carreño\\AppData\\Local\\Programs\\Python\\Python312\\Lib\\site-packages\\scikeras\\wrappers.py\", line 559, in _check_model_compatibility\n    if self.n_outputs_expected_ != len(self.model_.outputs):\n                                       ^^^^^^^^^^^^^^^^^^^\n  File \"C:\\Users\\Erick Carreño\\AppData\\Local\\Programs\\Python\\Python312\\Lib\\site-packages\\keras\\src\\models\\sequential.py\", line 292, in outputs\n    raise ValueError(\nValueError: Sequential model 'sequential_1' has no defined outputs yet.\n\n--------------------------------------------------------------------------------\n3 fits failed with the following error:\nTraceback (most recent call last):\n  File \"C:\\Users\\Erick Carreño\\AppData\\Local\\Programs\\Python\\Python312\\Lib\\site-packages\\sklearn\\model_selection\\_validation.py\", line 888, in _fit_and_score\n    estimator.fit(X_train, y_train, **fit_params)\n  File \"C:\\Users\\Erick Carreño\\AppData\\Local\\Programs\\Python\\Python312\\Lib\\site-packages\\scikeras\\wrappers.py\", line 1501, in fit\n    super().fit(X=X, y=y, sample_weight=sample_weight, **kwargs)\n  File \"C:\\Users\\Erick Carreño\\AppData\\Local\\Programs\\Python\\Python312\\Lib\\site-packages\\scikeras\\wrappers.py\", line 770, in fit\n    self._fit(\n  File \"C:\\Users\\Erick Carreño\\AppData\\Local\\Programs\\Python\\Python312\\Lib\\site-packages\\scikeras\\wrappers.py\", line 936, in _fit\n    self._check_model_compatibility(y)\n  File \"C:\\Users\\Erick Carreño\\AppData\\Local\\Programs\\Python\\Python312\\Lib\\site-packages\\scikeras\\wrappers.py\", line 559, in _check_model_compatibility\n    if self.n_outputs_expected_ != len(self.model_.outputs):\n                                       ^^^^^^^^^^^^^^^^^^^\n  File \"C:\\Users\\Erick Carreño\\AppData\\Local\\Programs\\Python\\Python312\\Lib\\site-packages\\keras\\src\\models\\sequential.py\", line 292, in outputs\n    raise ValueError(\nValueError: Sequential model 'sequential_2' has no defined outputs yet.\n\n--------------------------------------------------------------------------------\n3 fits failed with the following error:\nTraceback (most recent call last):\n  File \"C:\\Users\\Erick Carreño\\AppData\\Local\\Programs\\Python\\Python312\\Lib\\site-packages\\sklearn\\model_selection\\_validation.py\", line 888, in _fit_and_score\n    estimator.fit(X_train, y_train, **fit_params)\n  File \"C:\\Users\\Erick Carreño\\AppData\\Local\\Programs\\Python\\Python312\\Lib\\site-packages\\scikeras\\wrappers.py\", line 1501, in fit\n    super().fit(X=X, y=y, sample_weight=sample_weight, **kwargs)\n  File \"C:\\Users\\Erick Carreño\\AppData\\Local\\Programs\\Python\\Python312\\Lib\\site-packages\\scikeras\\wrappers.py\", line 770, in fit\n    self._fit(\n  File \"C:\\Users\\Erick Carreño\\AppData\\Local\\Programs\\Python\\Python312\\Lib\\site-packages\\scikeras\\wrappers.py\", line 936, in _fit\n    self._check_model_compatibility(y)\n  File \"C:\\Users\\Erick Carreño\\AppData\\Local\\Programs\\Python\\Python312\\Lib\\site-packages\\scikeras\\wrappers.py\", line 559, in _check_model_compatibility\n    if self.n_outputs_expected_ != len(self.model_.outputs):\n                                       ^^^^^^^^^^^^^^^^^^^\n  File \"C:\\Users\\Erick Carreño\\AppData\\Local\\Programs\\Python\\Python312\\Lib\\site-packages\\keras\\src\\models\\sequential.py\", line 292, in outputs\n    raise ValueError(\nValueError: Sequential model 'sequential_3' has no defined outputs yet.\n\n--------------------------------------------------------------------------------\n3 fits failed with the following error:\nTraceback (most recent call last):\n  File \"C:\\Users\\Erick Carreño\\AppData\\Local\\Programs\\Python\\Python312\\Lib\\site-packages\\sklearn\\model_selection\\_validation.py\", line 888, in _fit_and_score\n    estimator.fit(X_train, y_train, **fit_params)\n  File \"C:\\Users\\Erick Carreño\\AppData\\Local\\Programs\\Python\\Python312\\Lib\\site-packages\\scikeras\\wrappers.py\", line 1501, in fit\n    super().fit(X=X, y=y, sample_weight=sample_weight, **kwargs)\n  File \"C:\\Users\\Erick Carreño\\AppData\\Local\\Programs\\Python\\Python312\\Lib\\site-packages\\scikeras\\wrappers.py\", line 770, in fit\n    self._fit(\n  File \"C:\\Users\\Erick Carreño\\AppData\\Local\\Programs\\Python\\Python312\\Lib\\site-packages\\scikeras\\wrappers.py\", line 936, in _fit\n    self._check_model_compatibility(y)\n  File \"C:\\Users\\Erick Carreño\\AppData\\Local\\Programs\\Python\\Python312\\Lib\\site-packages\\scikeras\\wrappers.py\", line 559, in _check_model_compatibility\n    if self.n_outputs_expected_ != len(self.model_.outputs):\n                                       ^^^^^^^^^^^^^^^^^^^\n  File \"C:\\Users\\Erick Carreño\\AppData\\Local\\Programs\\Python\\Python312\\Lib\\site-packages\\keras\\src\\models\\sequential.py\", line 292, in outputs\n    raise ValueError(\nValueError: Sequential model 'sequential_4' has no defined outputs yet.\n\n--------------------------------------------------------------------------------\n3 fits failed with the following error:\nTraceback (most recent call last):\n  File \"C:\\Users\\Erick Carreño\\AppData\\Local\\Programs\\Python\\Python312\\Lib\\site-packages\\sklearn\\model_selection\\_validation.py\", line 888, in _fit_and_score\n    estimator.fit(X_train, y_train, **fit_params)\n  File \"C:\\Users\\Erick Carreño\\AppData\\Local\\Programs\\Python\\Python312\\Lib\\site-packages\\scikeras\\wrappers.py\", line 1501, in fit\n    super().fit(X=X, y=y, sample_weight=sample_weight, **kwargs)\n  File \"C:\\Users\\Erick Carreño\\AppData\\Local\\Programs\\Python\\Python312\\Lib\\site-packages\\scikeras\\wrappers.py\", line 770, in fit\n    self._fit(\n  File \"C:\\Users\\Erick Carreño\\AppData\\Local\\Programs\\Python\\Python312\\Lib\\site-packages\\scikeras\\wrappers.py\", line 936, in _fit\n    self._check_model_compatibility(y)\n  File \"C:\\Users\\Erick Carreño\\AppData\\Local\\Programs\\Python\\Python312\\Lib\\site-packages\\scikeras\\wrappers.py\", line 559, in _check_model_compatibility\n    if self.n_outputs_expected_ != len(self.model_.outputs):\n                                       ^^^^^^^^^^^^^^^^^^^\n  File \"C:\\Users\\Erick Carreño\\AppData\\Local\\Programs\\Python\\Python312\\Lib\\site-packages\\keras\\src\\models\\sequential.py\", line 292, in outputs\n    raise ValueError(\nValueError: Sequential model 'sequential_5' has no defined outputs yet.\n\n--------------------------------------------------------------------------------\n3 fits failed with the following error:\nTraceback (most recent call last):\n  File \"C:\\Users\\Erick Carreño\\AppData\\Local\\Programs\\Python\\Python312\\Lib\\site-packages\\sklearn\\model_selection\\_validation.py\", line 888, in _fit_and_score\n    estimator.fit(X_train, y_train, **fit_params)\n  File \"C:\\Users\\Erick Carreño\\AppData\\Local\\Programs\\Python\\Python312\\Lib\\site-packages\\scikeras\\wrappers.py\", line 1501, in fit\n    super().fit(X=X, y=y, sample_weight=sample_weight, **kwargs)\n  File \"C:\\Users\\Erick Carreño\\AppData\\Local\\Programs\\Python\\Python312\\Lib\\site-packages\\scikeras\\wrappers.py\", line 770, in fit\n    self._fit(\n  File \"C:\\Users\\Erick Carreño\\AppData\\Local\\Programs\\Python\\Python312\\Lib\\site-packages\\scikeras\\wrappers.py\", line 936, in _fit\n    self._check_model_compatibility(y)\n  File \"C:\\Users\\Erick Carreño\\AppData\\Local\\Programs\\Python\\Python312\\Lib\\site-packages\\scikeras\\wrappers.py\", line 559, in _check_model_compatibility\n    if self.n_outputs_expected_ != len(self.model_.outputs):\n                                       ^^^^^^^^^^^^^^^^^^^\n  File \"C:\\Users\\Erick Carreño\\AppData\\Local\\Programs\\Python\\Python312\\Lib\\site-packages\\keras\\src\\models\\sequential.py\", line 292, in outputs\n    raise ValueError(\nValueError: Sequential model 'sequential_6' has no defined outputs yet.\n\n--------------------------------------------------------------------------------\n1 fits failed with the following error:\nTraceback (most recent call last):\n  File \"C:\\Users\\Erick Carreño\\AppData\\Local\\Programs\\Python\\Python312\\Lib\\site-packages\\sklearn\\model_selection\\_validation.py\", line 888, in _fit_and_score\n    estimator.fit(X_train, y_train, **fit_params)\n  File \"C:\\Users\\Erick Carreño\\AppData\\Local\\Programs\\Python\\Python312\\Lib\\site-packages\\scikeras\\wrappers.py\", line 1501, in fit\n    super().fit(X=X, y=y, sample_weight=sample_weight, **kwargs)\n  File \"C:\\Users\\Erick Carreño\\AppData\\Local\\Programs\\Python\\Python312\\Lib\\site-packages\\scikeras\\wrappers.py\", line 770, in fit\n    self._fit(\n  File \"C:\\Users\\Erick Carreño\\AppData\\Local\\Programs\\Python\\Python312\\Lib\\site-packages\\scikeras\\wrappers.py\", line 936, in _fit\n    self._check_model_compatibility(y)\n  File \"C:\\Users\\Erick Carreño\\AppData\\Local\\Programs\\Python\\Python312\\Lib\\site-packages\\scikeras\\wrappers.py\", line 559, in _check_model_compatibility\n    if self.n_outputs_expected_ != len(self.model_.outputs):\n                                       ^^^^^^^^^^^^^^^^^^^\n  File \"C:\\Users\\Erick Carreño\\AppData\\Local\\Programs\\Python\\Python312\\Lib\\site-packages\\keras\\src\\models\\sequential.py\", line 292, in outputs\n    raise ValueError(\nValueError: Sequential model 'sequential_7' has no defined outputs yet.\n"
     ]
    }
   ],
   "source": [
    "# Verificación de la estructura del modelo\n",
    "temp_model = crear_modelo()\n",
    "temp_model.summary()\n",
    "\n",
    "# Sección 6: Optimización del Modelo con Algoritmo Genético (GA)\n",
    "from sklearn.model_selection import GridSearchCV\n",
    "from scikeras.wrappers import KerasClassifier\n",
    "from tensorflow.keras.optimizers import Adam\n",
    "from tensorflow.keras.models import Sequential\n",
    "from tensorflow.keras.layers import Embedding, LSTM, Dense, Dropout, Bidirectional\n",
    "\n",
    "def crear_modelo(lr=0.001, dropout_rate=0.5, lstm_units=64):\n",
    "    model = Sequential([\n",
    "        Embedding(input_dim=max_words, output_dim=embedding_dim, input_length=max_len),\n",
    "        Bidirectional(LSTM(lstm_units, return_sequences=True)),\n",
    "        Dropout(dropout_rate),\n",
    "        Bidirectional(LSTM(int(lstm_units / 2))),\n",
    "        Dense(3, activation='softmax')\n",
    "    ])\n",
    "    model.compile(optimizer=Adam(learning_rate=lr), loss='categorical_crossentropy', metrics=['accuracy'])\n",
    "    return model\n",
    "\n",
    "# Envolver el modelo Keras con KerasClassifier usando SciKeras\n",
    "model = KerasClassifier(\n",
    "    model=crear_modelo,\n",
    "    lr=0.001,\n",
    "    dropout_rate=0.5,\n",
    "    lstm_units=64,\n",
    "    epochs=10,\n",
    "    batch_size=32,\n",
    "    verbose=0\n",
    ")\n",
    "\n",
    "# Definición del espacio de búsqueda de hiperparámetros\n",
    "param_grid = {\n",
    "    'lr': [0.001, 0.01],\n",
    "    'dropout_rate': [0.3, 0.5],\n",
    "    'lstm_units': [32, 64]\n",
    "}\n",
    "\n",
    "# Realizar la búsqueda de hiperparámetros\n",
    "grid = GridSearchCV(estimator=model, param_grid=param_grid, n_jobs=-1, cv=3)\n",
    "\n",
    "try:\n",
    "    grid_result = grid.fit(X_train, y_train)\n",
    "except ValueError as e:\n",
    "    print(f\"Error durante el ajuste del modelo: {e}\")\n",
    "    raise\n",
    "\n",
    "# Resumen de los mejores resultados\n",
    "print(f\"Mejores parámetros: {grid_result.best_params_}\")\n",
    "print(f\"Mejor precisión: {grid_result.best_score_}\")\n",
    "\n",
    "# Evaluación del mejor modelo\n",
    "best_model = grid_result.best_estimator_.model_\n",
    "loss, accuracy = best_model.evaluate(X_test, y_test)\n",
    "print(f\"Pérdida del mejor modelo: {loss}\")\n",
    "print(f\"Precisión del mejor modelo: {accuracy}\")"
   ]
  },
  {
   "cell_type": "markdown",
   "id": "c7216aac-50dc-48e7-8ab4-f61b9ea5589c",
   "metadata": {},
   "source": [
    "# Sección 7: Visualización y Resultados"
   ]
  },
  {
   "cell_type": "code",
   "execution_count": null,
   "id": "852bc582-ae7a-49ee-9307-c52d8fe154a8",
   "metadata": {},
   "outputs": [],
   "source": [
    "# Sección 7: Visualización y Resultados\n",
    "import matplotlib.pyplot as plt\n",
    "import seaborn as sns\n",
    "import numpy as np\n",
    "\n",
    "# Mostrar resultados de evaluación\n",
    "def mostrar_resultados(history, y_test, y_pred):\n",
    "    # Historia del entrenamiento\n",
    "    plt.figure(figsize=(12, 5))\n",
    "    plt.subplot(1, 2, 1)\n",
    "    plt.plot(history.history['accuracy'], label='Precisión de entrenamiento')\n",
    "    plt.plot(history.history['val_accuracy'], label='Precisión de validación')\n",
    "    plt.xlabel('Época')\n",
    "    plt.ylabel('Precisión')\n",
    "    plt.legend()\n",
    "    plt.title('Precisión durante el entrenamiento')\n",
    "\n",
    "    plt.subplot(1, 2, 2)\n",
    "    plt.plot(history.history['loss'], label='Pérdida de entrenamiento')\n",
    "    plt.plot(history.history['val_loss'], label='Pérdida de validación')\n",
    "    plt.xlabel('Época')\n",
    "    plt.ylabel('Pérdida')\n",
    "    plt.legend()\n",
    "    plt.title('Pérdida durante el entrenamiento')\n",
    "    plt.show()\n",
    "\n",
    "    # Matriz de confusión\n",
    "    cm = confusion_matrix(y_test.argmax(axis=1), y_pred.argmax(axis=1))\n",
    "    plt.figure(figsize=(8, 6))\n",
    "    sns.heatmap(cm, annot=True, fmt='d', cmap='Blues', xticklabels=['Negativo', 'Neutral', 'Positivo'], yticklabels=['Negativo', 'Neutral', 'Positivo'])\n",
    "    plt.title('Matriz de Confusión')\n",
    "    plt.xlabel('Predicción')\n",
    "    plt.ylabel('Realidad')\n",
    "    plt.show()\n",
    "\n",
    "    # Reporte de clasificación\n",
    "    print('Reporte de Clasificación:')\n",
    "    print(classification_report(y_test.argmax(axis=1), y_pred.argmax(axis=1), target_names=['Negativo', 'Neutral', 'Positivo']))\n",
    "\n",
    "# Visualización de los resultados\n",
    "print(\"Mostrando visualizaciones...\")\n",
    "fig, axs = plt.subplots(2, 3, figsize=(18, 12))\n",
    "fig.suptitle('Análisis de Sentimientos y Aspectos', fontsize=16)\n",
    "\n",
    "# Distribución de Sentimientos\n",
    "sns.countplot(x='sentimiento', data=df, ax=axs[0, 0])\n",
    "axs[0, 0].set_title('Distribución de Sentimientos')\n",
    "\n",
    "# Número de Comentarios por Año\n",
    "df['timestamp'] = pd.to_datetime(df['timestamp'])\n",
    "df['year'] = df['timestamp'].dt.year\n",
    "sns.lineplot(x='year', y='comment', data=df.groupby('year').count().reset_index(), ax=axs[0, 1])\n",
    "axs[0, 1].set_title('Número de Comentarios por Año')\n",
    "\n",
    "# Palabras Más Frecuentes\n",
    "word_freq = pd.Series(np.concatenate(df['tokens'])).value_counts().head(20)\n",
    "word_freq.plot(kind='bar', ax=axs[0, 2])\n",
    "axs[0, 2].set_title('Palabras Más Frecuentes')\n",
    "\n",
    "# Distribución de Aspectos\n",
    "sns.countplot(x='aspecto', data=df, ax=axs[1, 0])\n",
    "axs[1, 0].set_title('Distribución de Aspectos')\n",
    "\n",
    "# Distribución de Opiniones por Año\n",
    "sns.histplot(data=df, x='year', hue='aspecto', multiple='stack', ax=axs[1, 1])\n",
    "axs[1, 1].set_title('Distribución de Opiniones por Año')\n",
    "\n",
    "# Matriz de Confusión (utilizando resultados del mejor modelo)\n",
    "y_pred = best_model.predict(X_test)\n",
    "cm = confusion_matrix(y_test.argmax(axis=1), y_pred.argmax(axis=1))\n",
    "sns.heatmap(cm, annot=True, fmt='d', cmap='Blues', ax=axs[1, 2], xticklabels=['Negativo', 'Neutral', 'Positivo'], yticklabels=['Negativo', 'Neutral', 'Positivo'])\n",
    "axs[1, 2].set_title('Matriz de Confusión')\n",
    "axs[1, 2].set_xlabel('Predicción')\n",
    "axs[1, 2].set_ylabel('Realidad')\n",
    "\n",
    "plt.tight_layout()\n",
    "plt.show()\n",
    "\n",
    "# Mostrar resultados del mejor modelo\n",
    "mostrar_resultados(history, y_test, y_pred)"
   ]
  }
 ],
 "metadata": {
  "kernelspec": {
   "display_name": "Python 3 (ipykernel)",
   "language": "python",
   "name": "python3"
  },
  "language_info": {
   "codemirror_mode": {
    "name": "ipython",
    "version": 3
   },
   "file_extension": ".py",
   "mimetype": "text/x-python",
   "name": "python",
   "nbconvert_exporter": "python",
   "pygments_lexer": "ipython3",
   "version": "3.12.1"
  }
 },
 "nbformat": 4,
 "nbformat_minor": 5
}
